
==============
Agent (vx.y.z)
==============

  Status date: 2022-12-20 22:52:01.796 UTC (1671576721796)
  Agent start: 2022-12-20 19:21:27.793 UTC (1671564087793)
  Pid: 12136
  Go Version: go1.18.8
  Python Version: 3.8.14
  Build arch: amd64
  Agent flavor: agent
  Check Runners: 4
  Log Level: INFO

  Paths
  =====
    Config File: /etc/datadog-agent/datadog.yaml
    conf.d: /etc/datadog-agent/conf.d
    checks.d: /etc/datadog-agent/checks.d

  Clocks
  ======
    NTP offset: 35Âµs
    System time: 2022-12-20 22:52:01.796 UTC (1671576721796)

  Host Info
  =========
    bootTime: 2022-12-20 19:19:03 UTC (1671563943000)
    hostId: d23fb05c-2393-9a7a-fbf3-92cd755df12a
    kernelArch: x86_64
    kernelVersion: 5.10.133+
    os: linux
    platform: cos
    platformVersion: 97
    procs: 211
    uptime: 2m37s
    virtualizationRole: guest

  Hostnames
  =========
    cluster-name: dd-sandbox
    host_aliases: [gke-dd-sandbox-bits-8943422b-5wpg-dd-sandbox gke-dd-sandbox-bits-8943422b-5wpg.c.datadog-sandbox.internal gke-dd-sandbox-bits-8943422b-5wpg.datadog-sandbox]
    hostname: gke-dd-sandbox-bits-8943422b-5wpg.c.datadog-sandbox.internal
    socket-fqdn: dd-datadog-c4kcx
    socket-hostname: dd-datadog-c4kcx
    host tags:
      cluster_name:dd-sandbox
      kube_cluster_name:dd-sandbox
      zone:asia-northeast1-a
      internal-hostname:gke-dd-sandbox-bits-8943422b-5wpg.c.datadog-sandbox.internal
      instance-id:90825865558996083
      project:datadog-sandbox
      numeric_project_id:958371799887
      cluster-name:dd-sandbox
      cluster-uid:3d6b7737edf6489fb1927577e24e8b0e314e6826aa3e47fa9b2eae419f261013
      cluster-location:asia-northeast1
    hostname provider: gce
    unused hostname providers:
      'hostname' configuration/environment: hostname is empty
      'hostname_file' configuration/environment: 'hostname_file' configuration is not enabled
      fargate: agent is not runnning on Fargate

  Metadata
  ========
    agent_version: x.y.z
    cloud_provider: GCP
    config_apm_dd_url: 
    config_dd_url: 
    config_logs_dd_url: 
    config_logs_socks5_proxy_address: 
    config_no_proxy: []
    config_process_dd_url: 
    config_proxy_http: 
    config_proxy_https: 
    config_site: 
    feature_apm_enabled: false
    feature_cspm_enabled: false
    feature_cws_enabled: false
    feature_logs_enabled: true
    feature_networks_enabled: false
    feature_networks_http_enabled: false
    feature_networks_https_enabled: false
    feature_otlp_enabled: false
    feature_process_enabled: false
    feature_processes_container_enabled: true
    flavor: agent
    hostname_source: gce
    install_method_installer_version: datadog-3.6.4
    install_method_tool: helm
    install_method_tool_version: Helm
    logs_transport: TCP

=========
Collector
=========

  Running Checks
  ==============
    
    cilium (2.3.0)
    --------------
      Instance ID: cilium:bac99095d52d45c [ERROR]
      Configuration Source: file:/etc/datadog-agent/conf.d/cilium.d/auto_conf.yaml
      Total Runs: 842
      Metric Samples: Last Run: 0, Total: 0
      Events: Last Run: 0, Total: 0
      Service Checks: Last Run: 1, Total: 842
      Average Execution Time : 8ms
      Last Execution Date : 2022-12-20 22:51:54 UTC (1671576714000)
      Last Successful Execution Date : Never
      Error: HTTPConnectionPool(host='10.146.15.207', port=9090): Max retries exceeded with url: /metrics (Caused by NewConnectionError('<urllib3.connection.HTTPConnection object at 0x7f20296ba430>: Failed to establish a new connection: [Errno 111] Connection refused'))
      Traceback (most recent call last):
        File "/opt/datadog-agent/embedded/lib/python3.8/site-packages/urllib3/connection.py", line 174, in _new_conn
          conn = connection.create_connection(
        File "/opt/datadog-agent/embedded/lib/python3.8/site-packages/urllib3/util/connection.py", line 95, in create_connection
          raise err
        File "/opt/datadog-agent/embedded/lib/python3.8/site-packages/urllib3/util/connection.py", line 85, in create_connection
          sock.connect(sa)
      ConnectionRefusedError: [Errno 111] Connection refused
      
      During handling of the above exception, another exception occurred:
      
      Traceback (most recent call last):
        File "/opt/datadog-agent/embedded/lib/python3.8/site-packages/urllib3/connectionpool.py", line 703, in urlopen
          httplib_response = self._make_request(
        File "/opt/datadog-agent/embedded/lib/python3.8/site-packages/urllib3/connectionpool.py", line 398, in _make_request
          conn.request(method, url, **httplib_request_kw)
        File "/opt/datadog-agent/embedded/lib/python3.8/site-packages/urllib3/connection.py", line 239, in request
          super(HTTPConnection, self).request(method, url, body=body, headers=headers)
        File "/opt/datadog-agent/embedded/lib/python3.8/http/client.py", line 1256, in request
          self._send_request(method, url, body, headers, encode_chunked)
        File "/opt/datadog-agent/embedded/lib/python3.8/http/client.py", line 1302, in _send_request
          self.endheaders(body, encode_chunked=encode_chunked)
        File "/opt/datadog-agent/embedded/lib/python3.8/http/client.py", line 1251, in endheaders
          self._send_output(message_body, encode_chunked=encode_chunked)
        File "/opt/datadog-agent/embedded/lib/python3.8/http/client.py", line 1011, in _send_output
          self.send(msg)
        File "/opt/datadog-agent/embedded/lib/python3.8/http/client.py", line 951, in send
          self.connect()
        File "/opt/datadog-agent/embedded/lib/python3.8/site-packages/urllib3/connection.py", line 205, in connect
          conn = self._new_conn()
        File "/opt/datadog-agent/embedded/lib/python3.8/site-packages/urllib3/connection.py", line 186, in _new_conn
          raise NewConnectionError(
      urllib3.exceptions.NewConnectionError: <urllib3.connection.HTTPConnection object at 0x7f20296ba430>: Failed to establish a new connection: [Errno 111] Connection refused
      
      During handling of the above exception, another exception occurred:
      
      Traceback (most recent call last):
        File "/opt/datadog-agent/embedded/lib/python3.8/site-packages/requests/adapters.py", line 489, in send
          resp = conn.urlopen(
        File "/opt/datadog-agent/embedded/lib/python3.8/site-packages/urllib3/connectionpool.py", line 787, in urlopen
          retries = retries.increment(
        File "/opt/datadog-agent/embedded/lib/python3.8/site-packages/urllib3/util/retry.py", line 592, in increment
          raise MaxRetryError(_pool, url, error or ResponseError(cause))
      urllib3.exceptions.MaxRetryError: HTTPConnectionPool(host='10.146.15.207', port=9090): Max retries exceeded with url: /metrics (Caused by NewConnectionError('<urllib3.connection.HTTPConnection object at 0x7f20296ba430>: Failed to establish a new connection: [Errno 111] Connection refused'))
      
      During handling of the above exception, another exception occurred:
      
      Traceback (most recent call last):
        File "/opt/datadog-agent/embedded/lib/python3.8/site-packages/datadog_checks/base/checks/base.py", line 1122, in run
          self.check(instance)
        File "/opt/datadog-agent/embedded/lib/python3.8/site-packages/datadog_checks/base/checks/openmetrics/base_check.py", line 142, in check
          self.process(scraper_config)
        File "/opt/datadog-agent/embedded/lib/python3.8/site-packages/datadog_checks/base/checks/openmetrics/mixins.py", line 573, in process
          for metric in self.scrape_metrics(scraper_config):
        File "/opt/datadog-agent/embedded/lib/python3.8/site-packages/datadog_checks/base/checks/openmetrics/mixins.py", line 500, in scrape_metrics
          response = self.poll(scraper_config)
        File "/opt/datadog-agent/embedded/lib/python3.8/site-packages/datadog_checks/base/checks/openmetrics/mixins.py", line 837, in poll
          response = self.send_request(endpoint, scraper_config, headers)
        File "/opt/datadog-agent/embedded/lib/python3.8/site-packages/datadog_checks/base/checks/openmetrics/mixins.py", line 863, in send_request
          return http_handler.get(endpoint, stream=True, **kwargs)
        File "/opt/datadog-agent/embedded/lib/python3.8/site-packages/datadog_checks/base/utils/http.py", line 356, in get
          return self._request('get', url, options)
        File "/opt/datadog-agent/embedded/lib/python3.8/site-packages/datadog_checks/base/utils/http.py", line 420, in _request
          response = self.make_request_aia_chasing(request_method, method, url, new_options, persist)
        File "/opt/datadog-agent/embedded/lib/python3.8/site-packages/datadog_checks/base/utils/http.py", line 426, in make_request_aia_chasing
          response = request_method(url, **new_options)
        File "/opt/datadog-agent/embedded/lib/python3.8/site-packages/requests/api.py", line 73, in get
          return request("get", url, params=params, **kwargs)
        File "/opt/datadog-agent/embedded/lib/python3.8/site-packages/requests/api.py", line 59, in request
          return session.request(method=method, url=url, **kwargs)
        File "/opt/datadog-agent/embedded/lib/python3.8/site-packages/requests/sessions.py", line 587, in request
          resp = self.send(prep, **send_kwargs)
        File "/opt/datadog-agent/embedded/lib/python3.8/site-packages/requests/sessions.py", line 701, in send
          r = adapter.send(request, **kwargs)
        File "/opt/datadog-agent/embedded/lib/python3.8/site-packages/requests/adapters.py", line 565, in send
          raise ConnectionError(e, request=request)
      requests.exceptions.ConnectionError: HTTPConnectionPool(host='10.146.15.207', port=9090): Max retries exceeded with url: /metrics (Caused by NewConnectionError('<urllib3.connection.HTTPConnection object at 0x7f20296ba430>: Failed to establish a new connection: [Errno 111] Connection refused'))
    
    datadog_cluster_agent (2.4.0)
    -----------------------------
      Instance ID: datadog_cluster_agent:4b0f56c49d48c92e [OK]
      Configuration Source: file:/etc/datadog-agent/conf.d/datadog_cluster_agent.d/auto_conf.yaml
      Total Runs: 842
      Metric Samples: Last Run: 125, Total: 104,832
      Events: Last Run: 0, Total: 0
      Service Checks: Last Run: 1, Total: 842
      Average Execution Time : 29ms
      Last Execution Date : 2022-12-20 22:52:01 UTC (1671576721000)
      Last Successful Execution Date : 2022-12-20 22:52:01 UTC (1671576721000)
      
      Instance ID: datadog_cluster_agent:79dc7329a0398f09 [OK]
      Configuration Source: file:/etc/datadog-agent/conf.d/datadog_cluster_agent.d/auto_conf.yaml
      Total Runs: 838
      Metric Samples: Last Run: 61, Total: 50,672
      Events: Last Run: 0, Total: 0
      Service Checks: Last Run: 1, Total: 838
      Average Execution Time : 25ms
      Last Execution Date : 2022-12-20 22:51:59 UTC (1671576719000)
      Last Successful Execution Date : 2022-12-20 22:51:59 UTC (1671576719000)
      
    
    network (2.9.2)
    ---------------
      Instance ID: network:d884b5186b651429 [OK]
      Configuration Source: file:/etc/datadog-agent/conf.d/network.d/conf.yaml.default
      Total Runs: 841
      Metric Samples: Last Run: 174, Total: 146,334
      Events: Last Run: 0, Total: 0
      Service Checks: Last Run: 0, Total: 0
      Average Execution Time : 6ms
      Last Execution Date : 2022-12-20 22:51:48 UTC (1671576708000)
      Last Successful Execution Date : 2022-12-20 22:51:48 UTC (1671576708000)
      
  Check Initialization Errors
  ===========================

    
      postgres (13.1.0)
      -----------------

      instance 0:

        could not invoke 'postgres' python check constructor. New constructor API returned:
Traceback (most recent call last):
  File "/opt/datadog-agent/embedded/lib/python3.8/site-packages/datadog_checks/postgres/postgres.py", line 62, in __init__
    self._config = PostgresConfig(self.instance)
  File "/opt/datadog-agent/embedded/lib/python3.8/site-packages/datadog_checks/postgres/config.py", line 35, in __init__
    raise ConfigurationError('Please specify a user to connect to Postgres.')
datadog_checks.base.errors.ConfigurationError: Please specify a user to connect to Postgres.
Deprecated constructor API returned:
__init__() got an unexpected keyword argument 'agentConfig'
  Loading Errors
  ==============
    postgres
    --------
      Core Check Loader:
        Check postgres not found in Catalog
        
      JMX Check Loader:
        check is not a jmx check, or unable to determine if it's so
        
      Python Check Loader:
        could not configure check instance for python check postgres: could not invoke 'postgres' python check constructor. New constructor API returned:
Traceback (most recent call last):
  File "/opt/datadog-agent/embedded/lib/python3.8/site-packages/datadog_checks/postgres/postgres.py", line 62, in __init__
    self._config = PostgresConfig(self.instance)
  File "/opt/datadog-agent/embedded/lib/python3.8/site-packages/datadog_checks/postgres/config.py", line 35, in __init__
    raise ConfigurationError('Please specify a user to connect to Postgres.')
datadog_checks.base.errors.ConfigurationError: Please specify a user to connect to Postgres.
Deprecated constructor API returned:
__init__() got an unexpected keyword argument 'agentConfig'
        
========
JMXFetch
========

  Information
  ==================
  Initialized checks
  ==================
    no checks
    
  Failed checks
  =============
    no checks
    
=========
Forwarder
=========

  Transactions
  ============
    Cluster: 0
    ClusterRole: 0
    ClusterRoleBinding: 0
    CronJob: 0
    DaemonSet: 0
    Deployment: 0
    Dropped: 0
    HighPriorityQueueFull: 0
    Ingress: 0
    Job: 0
    Namespace: 0
    Node: 0
    PersistentVolume: 0
    PersistentVolumeClaim: 0
    Pod: 0
    ReplicaSet: 0
    Requeued: 0
    Retried: 0
    RetryQueueSize: 0
    Role: 0
    RoleBinding: 0
    Service: 0
    ServiceAccount: 0
    StatefulSet: 0

  Transaction Successes
  =====================
    Total number: 1775
    Successes By Endpoint:
      check_run_v1: 841
      intake: 72
      metadata_v1: 21
      series_v2: 841

  On-disk storage
  ===============
    On-disk storage is disabled. Configure `forwarder_storage_max_size_in_bytes` to enable it.

  API Keys status
  ===============
    API key ending with 841ae: API Key valid

==========
Endpoints
==========
  https://app.datadoghq.com - API Key ending with:
      - 841ae

==========
Logs Agent
==========

    Reliable: Sending uncompressed logs in SSL encrypted TCP to agent-intake.logs.datadoghq.com on port 10516

    You are currently sending Logs to Datadog through TCP (either because logs_config.force_use_tcp or logs_config.socks5_proxy_address is set or the HTTP connectivity test has failed). To benefit from increased reliability and better network performances, we strongly encourage switching over to compressed HTTPS which is now the default protocol.

    BytesSent: 1.8474997e+07
    EncodedBytesSent: 1.8474997e+07
    LogsProcessed: 10438
    LogsSent: 10438
  ============
  Integrations
  ============

  kube-system/pdcsi-node-vmxbk/gce-pd-driver
  ------------------------------------------
    - Type: file
      Identifier: 401a8645147ae8ef2baf2a5187c22b61554a64c5e0800b481c7a6a6e2e5e9d53
      Path: /var/log/pods/kube-system_pdcsi-node-vmxbk_8194ece2-46dd-495e-9220-3a6b88fa4d61/gce-pd-driver/*.log
      Service: gcp-compute-persistent-disk-csi-driver
      Source: gcp-compute-persistent-disk-csi-driver
      Status: OK
        1 files tailed out of 1 files matching
      Inputs:
        /var/log/pods/kube-system_pdcsi-node-vmxbk_8194ece2-46dd-495e-9220-3a6b88fa4d61/gce-pd-driver/0.log

  kube-system/l7-default-backend-6dc845c45d-xlnmh/default-http-backend
  --------------------------------------------------------------------
    - Type: file
      Identifier: 0f23fbf70ab6cb8063cacb65bf7c7472a6e4062838764cac256439070942f161
      Path: /var/log/pods/kube-system_l7-default-backend-6dc845c45d-xlnmh_85840891-57e7-4fd4-8c1d-9a7ec5227614/default-http-backend/*.log
      Service: ingress-gce-404-server-with-metrics
      Source: ingress-gce-404-server-with-metrics
      Status: OK
        1 files tailed out of 1 files matching
      Inputs:
        /var/log/pods/kube-system_l7-default-backend-6dc845c45d-xlnmh_85840891-57e7-4fd4-8c1d-9a7ec5227614/default-http-backend/0.log



=============
Process Agent
=============

  Version: x.y.z
  Status date: 2022-12-20 22:52:01.802 UTC (1671576721802)
  Process Agent Start: 2022-12-20 19:21:28.069 UTC (1671564088069)
  Pid: 12223
  Go Version: go1.18.8
  Build arch: amd64
  Log Level: INFO
  Enabled Checks: [container rtcontainer pod]
  Allocated Memory: 35,295,544 bytes
  Hostname: gke-dd-sandbox-bits-8943422b-5wpg.c.datadog-sandbox.internal
  System Probe Process Module Status: Not running
  Process Language Detection Enabled: False

  =================
  Process Endpoints
  =================
    https://process.datadoghq.com - API Key ending with:
        - 841ae

  =========
  Collector
  =========
    Last collection time: 2022-12-20 22:51:56
    Docker socket: 
    Number of processes: 0
    Number of containers: 25
    Process Queue length: 0
    RTProcess Queue length: 0
    Connections Queue length: 0
    Event Queue length: 0
    Pod Queue length: 0
    Process Bytes enqueued: 0
    RTProcess Bytes enqueued: 0
    Connections Bytes enqueued: 0
    Event Bytes enqueued: 0
    Pod Bytes enqueued: 0
    Drop Check Payloads: []

  ==========
  Extractors
  ==========

    Workloadmeta
    ============
      Cache size: <no value>
      Stale diffs discarded: <no value>
      Diffs dropped: <no value>

=========
APM Agent
=========
  Status: Running
  Pid: 12174
  Uptime: 12633 seconds
  Mem alloc: 9,203,488 bytes
  Hostname: gke-dd-sandbox-bits-8943422b-5wpg.c.datadog-sandbox.internal
  Receiver: 0.0.0.0:8126
  Endpoints:
    https://trace.agent.datadoghq.com

  Receiver (previous minute)
  ==========================
    No traces received in the previous minute.
    

  Writer (previous minute)
  ========================
    Traces: 0 payloads, 0 traces, 0 events, 0 bytes
    Stats: 0 payloads, 0 stats buckets, 0 bytes

==========
Aggregator
==========
  Checks Metric Sample: 3,800,535
  Dogstatsd Metric Sample: 136,758
  Event: 1
  Events Flushed: 1
  Number Of Flushes: 841
  Series Flushed: 3,224,651
  Service Check: 25,700
  Service Checks Flushed: 26,509

=========
DogStatsD
=========
  Event Packets: 0
  Event Parse Errors: 0
  Metric Packets: 136,757
  Metric Parse Errors: 0
  Service Check Packets: 0
  Service Check Parse Errors: 0
  Udp Bytes: 21,336,530
  Udp Packet Reading Errors: 0
  Udp Packets: 76,232
  Uds Bytes: 0
  Uds Origin Detection Errors: 0
  Uds Packet Reading Errors: 0
  Uds Packets: 1
  Unterminated Metric Errors: 0

Tip: For troubleshooting, enable 'dogstatsd_metrics_stats_enable' in the main datadog.yaml file to generate Dogstatsd logs. Once 'dogstatsd_metrics_stats_enable' is enabled, users can also use 'dogstatsd-stats' command to get visibility of the latest collected metrics.
=====================
Datadog Cluster Agent
=====================
  
    - Datadog Cluster Agent endpoint detected: https://10.122.58.252:5005
    Successfully connected to the Datadog Cluster Agent.
    - Running: x.y.z+commit.9b0b54b

==========
SNMP Traps
==========
  Packets: 0
  Packets Unknown Community String: 0

=============
Autodiscovery
=============
  Enabled Features
  ================
    containerd
    cri
    docker
    kubernetes

====================
Remote Configuration
====================
    
    Remote Configuration is disabled
    

====
OTLP
====

  Status: Not enabled
  Collector status: Not running
  